outputs/trades_InventoryAndVolatilityAdjusted_BuyPressure.csv
timestamp,strategy,regime,price,quantity,mm_bought,mm_sold
2,InventoryAndVolatilityAdjusted,BuyPressure,99.950000,18,0,0
4,InventoryAndVolatilityAdjusted,BuyPressure,100.050000,12,0,0
5,InventoryAndVolatilityAdjusted,BuyPressure,100.050000,15,0,0
8,InventoryAndVolatilityAdjusted,BuyPressure,99.960506,3,0,0
9,InventoryAndVolatilityAdjusted,BuyPressure,100.050000,19,0,0
10,InventoryAndVolatilityAdjusted,BuyPressure,99.960506,6,0,0
10,InventoryAndVolatilityAdjusted,BuyPressure,99.950000,10,0,0
11,InventoryAndVolatilityAdjusted,BuyPressure,100.037021,10,0,1
11,InventoryAndVolatilityAdjusted,BuyPressure,100.050000,4,0,0
11,InventoryAndVolatilityAdjusted,BuyPressure,100.050015,1,0,0
12,InventoryAndVolatilityAdjusted,BuyPressure,100.050015,14,0,0
12,InventoryAndVolatilityAdjusted,BuyPressure,100.100000,3,0,0
13,InventoryAndVolatilityAdjusted,BuyPressure,100.100000,2,0,0
14,InventoryAndVolatilityAdjusted,BuyPressure,100.100000,3,0,0
17,InventoryAndVolatilityAdjusted,BuyPressure,99.959591,12,0,0
17,InventoryAndVolatilityAdjusted,BuyPressure,99.950000,7,0,0
18,InventoryAndVolatilityAdjusted,BuyPressure,99.950000,13,0,0
20,InventoryAndVolatilityAdjusted,BuyPressure,100.100000,6,0,0
20,InventoryAndVolatilityAdjusted,BuyPressure,100.100000,10,1,0
23,InventoryAndVolatilityAdjusted,BuyPressure,100.100000,14,0,0
25,InventoryAndVolatilityAdjusted,BuyPressure,100.044191,3,0,0
27,InventoryAndVolatilityAdjusted,BuyPressure,100.044191,8,0,0
30,InventoryAndVolatilityAdjusted,BuyPressure,100.044191,9,0,0
30,InventoryAndVolatilityAdjusted,BuyPressure,99.995360,2,0,0
36,InventoryAndVolatilityAdjusted,BuyPressure,100.076343,10,0,1
36,InventoryAndVolatilityAdjusted,BuyPressure,100.100000,9,0,0
37,InventoryAndVolatilityAdjusted,BuyPressure,100.100000,3,0,0
37,InventoryAndVolatilityAdjusted,BuyPressure,100.150000,5,0,0
39,InventoryAndVolatilityAdjusted,BuyPressure,100.150000,1,0,0
40,InventoryAndVolatilityAdjusted,BuyPressure,99.995360,9,0,0
40,InventoryAndVolatilityAdjusted,BuyPressure,99.977829,11,0,0
42,InventoryAndVolatilityAdjusted,BuyPressure,100.131130,10,1,0
42,InventoryAndVolatilityAdjusted,BuyPressure,99.977829,1,0,0
43,InventoryAndVolatilityAdjusted,BuyPressure,99.977829,3,0,0
43,InventoryAndVolatilityAdjusted,BuyPressure,99.972885,5,0,0
46,InventoryAndVolatilityAdjusted,BuyPressure,100.150000,5,0,0
49,InventoryAndVolatilityAdjusted,BuyPressure,100.150000,11,0,0
51,InventoryAndVolatilityAdjusted,BuyPressure,100.106562,10,0,1
51,InventoryAndVolatilityAdjusted,BuyPressure,100.150000,7,0,0
54,InventoryAndVolatilityAdjusted,BuyPressure,100.150000,11,0,0
55,InventoryAndVolatilityAdjusted,BuyPressure,100.150000,3,0,0
57,InventoryAndVolatilityAdjusted,BuyPressure,100.049926,8,0,0
57,InventoryAndVolatilityAdjusted,BuyPressure,100.039594,1,0,0
57,InventoryAndVolatilityAdjusted,BuyPressure,99.985828,3,1,0
58,InventoryAndVolatilityAdjusted,BuyPressure,100.150000,7,0,0
58,InventoryAndVolatilityAdjusted,BuyPressure,100.164764,7,0,0
60,InventoryAndVolatilityAdjusted,BuyPressure,100.164764,9,0,0
61,InventoryAndVolatilityAdjusted,BuyPressure,100.173528,8,0,0
61,InventoryAndVolatilityAdjusted,BuyPressure,100.179234,2,0,0
62,InventoryAndVolatilityAdjusted,BuyPressure,100.179234,11,0,0
62,InventoryAndVolatilityAdjusted,BuyPressure,100.200000,2,0,0
64,InventoryAndVolatilityAdjusted,BuyPressure,100.124390,3,1,0
67,InventoryAndVolatilityAdjusted,BuyPressure,100.124390,7,1,0
68,InventoryAndVolatilityAdjusted,BuyPressure,99.985828,7,1,0
68,InventoryAndVolatilityAdjusted,BuyPressure,99.972885,2,0,0
72,InventoryAndVolatilityAdjusted,BuyPressure,99.989794,4,0,1
73,InventoryAndVolatilityAdjusted,BuyPressure,99.989794,6,0,1
73,InventoryAndVolatilityAdjusted,BuyPressure,100.111603,3,0,0
73,InventoryAndVolatilityAdjusted,BuyPressure,100.130587,1,0,0
74,InventoryAndVolatilityAdjusted,BuyPressure,99.983849,14,0,0
75,InventoryAndVolatilityAdjusted,BuyPressure,100.130587,8,0,0
76,InventoryAndVolatilityAdjusted,BuyPressure,99.972885,4,0,0
76,InventoryAndVolatilityAdjusted,BuyPressure,99.969923,5,0,0
76,InventoryAndVolatilityAdjusted,BuyPressure,99.969867,1,0,0
77,InventoryAndVolatilityAdjusted,BuyPressure,99.969867,9,0,0
80,InventoryAndVolatilityAdjusted,BuyPressure,100.130587,1,0,0
80,InventoryAndVolatilityAdjusted,BuyPressure,100.138831,1,0,0
83,InventoryAndVolatilityAdjusted,BuyPressure,100.046414,2,0,0
83,InventoryAndVolatilityAdjusted,BuyPressure,100.031910,5,1,0
85,InventoryAndVolatilityAdjusted,BuyPressure,100.138831,8,0,0
87,InventoryAndVolatilityAdjusted,BuyPressure,100.138831,7,0,0
87,InventoryAndVolatilityAdjusted,BuyPressure,100.151170,5,0,0
87,InventoryAndVolatilityAdjusted,BuyPressure,100.153495,7,0,1
88,InventoryAndVolatilityAdjusted,BuyPressure,100.153495,3,0,1
88,InventoryAndVolatilityAdjusted,BuyPressure,100.158348,9,0,0
89,InventoryAndVolatilityAdjusted,BuyPressure,100.200000,17,0,0
90,InventoryAndVolatilityAdjusted,BuyPressure,100.200000,7,0,0
91,InventoryAndVolatilityAdjusted,BuyPressure,100.200000,6,0,0
93,InventoryAndVolatilityAdjusted,BuyPressure,100.165107,9,1,0
94,InventoryAndVolatilityAdjusted,BuyPressure,100.165107,1,1,0
94,InventoryAndVolatilityAdjusted,BuyPressure,100.038944,13,0,0
95,InventoryAndVolatilityAdjusted,BuyPressure,100.200000,18,0,0
96,InventoryAndVolatilityAdjusted,BuyPressure,100.201812,10,0,0
97,InventoryAndVolatilityAdjusted,BuyPressure,100.201812,5,0,0
97,InventoryAndVolatilityAdjusted,BuyPressure,100.206036,13,0,0
99,InventoryAndVolatilityAdjusted,BuyPressure,100.206036,3,0,0
102,InventoryAndVolatilityAdjusted,BuyPressure,100.190959,10,0,1
103,InventoryAndVolatilityAdjusted,BuyPressure,100.063194,10,1,0
103,InventoryAndVolatilityAdjusted,BuyPressure,100.054034,8,0,0
104,InventoryAndVolatilityAdjusted,BuyPressure,100.054034,6,0,0
104,InventoryAndVolatilityAdjusted,BuyPressure,100.038944,3,0,0
105,InventoryAndVolatilityAdjusted,BuyPressure,100.038944,4,0,0
105,InventoryAndVolatilityAdjusted,BuyPressure,100.031910,5,1,0
105,InventoryAndVolatilityAdjusted,BuyPressure,100.012540,3,0,0
106,InventoryAndVolatilityAdjusted,BuyPressure,100.206396,17,0,0
106,InventoryAndVolatilityAdjusted,BuyPressure,100.229828,2,0,0
108,InventoryAndVolatilityAdjusted,BuyPressure,100.114301,8,0,0
109,InventoryAndVolatilityAdjusted,BuyPressure,100.245410,7,0,1
110,InventoryAndVolatilityAdjusted,BuyPressure,100.245410,3,0,1
110,InventoryAndVolatilityAdjusted,BuyPressure,100.245630,4,0,0
113,InventoryAndVolatilityAdjusted,BuyPressure,100.125767,10,1,0
113,InventoryAndVolatilityAdjusted,BuyPressure,100.114701,3,0,0
115,InventoryAndVolatilityAdjusted,BuyPressure,100.073296,8,0,0
118,InventoryAndVolatilityAdjusted,BuyPressure,100.214584,5,0,0
118,InventoryAndVolatilityAdjusted,BuyPressure,100.245630,8,0,0
120,InventoryAndVolatilityAdjusted,BuyPressure,100.144868,1,0,1
120,InventoryAndVolatilityAdjusted,BuyPressure,100.102991,7,0,1
121,InventoryAndVolatilityAdjusted,BuyPressure,100.073296,5,0,0
121,InventoryAndVolatilityAdjusted,BuyPressure,100.012540,11,0,0
122,InventoryAndVolatilityAdjusted,BuyPressure,100.012540,3,0,0
122,InventoryAndVolatilityAdjusted,BuyPressure,100.011262,15,0,0
122,InventoryAndVolatilityAdjusted,BuyPressure,100.002669,2,0,0
123,InventoryAndVolatilityAdjusted,BuyPressure,100.093451,2,0,1
123,InventoryAndVolatilityAdjusted,BuyPressure,100.202213,10,0,0
125,InventoryAndVolatilityAdjusted,BuyPressure,100.002669,13,0,0
125,InventoryAndVolatilityAdjusted,BuyPressure,100.001087,2,0,0
125,InventoryAndVolatilityAdjusted,BuyPressure,99.970936,5,1,0
131,InventoryAndVolatilityAdjusted,BuyPressure,100.146248,4,0,1
133,InventoryAndVolatilityAdjusted,BuyPressure,100.064100,8,0,0
133,InventoryAndVolatilityAdjusted,BuyPressure,100.035780,7,0,0
133,InventoryAndVolatilityAdjusted,BuyPressure,100.025035,4,1,0
135,InventoryAndVolatilityAdjusted,BuyPressure,100.146248,6,0,1
135,InventoryAndVolatilityAdjusted,BuyPressure,100.202213,7,0,0
135,InventoryAndVolatilityAdjusted,BuyPressure,100.227532,3,0,0
140,InventoryAndVolatilityAdjusted,BuyPressure,100.193446,6,0,0
141,InventoryAndVolatilityAdjusted,BuyPressure,100.138369,7,1,0
